<?xml version="1.0" ?>
<robot name="Robot">
  <!--Generated by RobotCAD, a ROS Workbench for FreeCAD (https://github.com/drfenixion/freecad.robotcad)-->
  <link name="l_Base_link001">
    <visual>
      <!--Base_link001/Base_link001.-->
      <origin rpy="0 0 0" xyz="0.10 0.10 0.10"/>
      <geometry>
        <mesh filename="package://robot_3dof/meshes/unnamed_base_link_dabvl7.dae"/>
      </geometry>
    </visual>
    <inertial>
      <mass value="0.8927620923338794"/>
      <origin rpy="0 0 0" xyz="0.1 0.1 0.127945"/>
      <inertia ixx="0.000695468727359832" ixy="5.460941560537486e-20" ixz="7.16853779984661e-20" iyy="0.0006954687273598237" iyz="1.4405122220039796e-20" izz="0.0008079656005749738"/>
    </inertial>
  </link>
  <link name="l_Link_004">
    <visual>
      <!--Link_004/Link_002.-->
      <origin rpy="0 0 0" xyz="0.0 0.0 -0.01"/>
      <geometry>
        <mesh filename="package://robot_3dof/meshes/unnamed_link_1_hibykz.dae"/>
      </geometry>
    </visual>
    <inertial>
      <mass value="0.18582946919401871"/>
      <origin rpy="0 0 0" xyz="0.0 0.0 0.00187359"/>
      <inertia ixx="8.833631389763842e-05" ixy="-1.7543718948538604e-12" ixz="1.3607460298830032e-12" iyy="8.640163361952176e-05" iyz="4.436450979034198e-18" izz="0.00011778880512837618"/>
    </inertial>
  </link>
  <link name="l_Link_005">
    <visual>
      <!--Link_005/Link_003.-->
      <origin rpy="1.5707963267948963 0 0" xyz="0.14 0.0 0.005"/>
      <geometry>
        <mesh filename="package://robot_3dof/meshes/unnamed_link_2_gw5afc.dae"/>
      </geometry>
    </visual>
    <inertial>
      <mass value="0.2742411500823461"/>
      <origin rpy="1.5707963267948963 0 0" xyz="0.14 0.0 0.005"/>
      <inertia ixx="1.8326924685514177e-05" ixy="1.0058283805847166e-20" ixz="-2.6154096544054464e-21" iyy="0.0015695776449461912" iyz="1.7352256790993985e-21" izz="0.0015695334662994996"/>
    </inertial>
  </link>
  <link name="l_Link_006">
    <visual>
      <!--Link_006/Link_004.-->
      <origin rpy="1.5707963267948963 0 0" xyz="0.14 0.0 0.005"/>
      <geometry>
        <mesh filename="package://robot_3dof/meshes/unnamed_link_3_bdrbm1.dae"/>
      </geometry>
    </visual>
    <inertial>
      <mass value="0.2742411500823461"/>
      <origin rpy="1.5707963267948963 0 0" xyz="0.14 0.0 0.005"/>
      <inertia ixx="1.8326924685514177e-05" ixy="1.0058283805847166e-20" ixz="-2.6154096544054464e-21" iyy="0.0015695776449461912" iyz="1.7352256790993985e-21" izz="0.0015695334662994996"/>
    </inertial>
  </link>
  <joint name="l_Base_link001__to__l_Link_004" type="continuous">
    <parent link="l_Base_link001"/>
    <child link="l_Link_004"/>
    <origin rpy="0 0 3.141592653589793" xyz="0.1 0.1 0.17"/>
    <axis xyz="0 0 1"/>
  </joint>
  <joint name="l_Link_004__to__l_Link_005" type="continuous">
    <parent link="l_Link_004"/>
    <child link="l_Link_005"/>
    <origin rpy="-1.5707963267948963 0 0" xyz="0.0 -0.005 0.0249785"/>
    <axis xyz="0 0 1"/>
  </joint>
  <joint name="l_Link_005__to__l_Link_006" type="continuous">
    <parent link="l_Link_005"/>
    <child link="l_Link_006"/>
    <origin rpy="0 0 0" xyz="0.28 0.0 0.0"/>
    <axis xyz="0 0 1"/>
  </joint>
</robot>
